Workbook
Name NumEval: 'Cálculo de % usabilidad'!$F$4
Name Relenacia: Valores!$J$5:$J$8
Name Relevancia: Valores!$J$5:$J$8
Name Tabla621: 'Tablas de relevancia'!$A$4:$Q$13
Name Tabla622: 'Tablas de relevancia'!$A$18:$Q$24
Name Tabla623: 'Tablas de relevancia'!$A$29:$Q$42
Name Tabla624: 'Tablas de relevancia'!$A$47:$Q$52
Name Tabla625: 'Tablas de relevancia'!$A$57:$Q$66
Name Tabla626: 'Tablas de relevancia'!$A$71:$Q$77
Name Tabla627: 'Tablas de relevancia'!$A$82:$Q$91
Name Tabla628: 'Tablas de relevancia'!$A$96:$Q$101
Name Tabla629: 'Tablas de relevancia'!$A$106:$Q$113
Name Tabla630: 'Tablas de relevancia'!$A$118:$Q$122
Name TipoDeSitio: 'Datos sitio'!$B$15
Name Tipos: Valores!$E$5:$E$20
Name Valores1: Valores!$A$5:$A$16
Name Valores2: Valores!$C$5:$C$10
Name ValoresRC: Valores!$J$5:$K$8
Name ValoresVC: Valores!$M$5:$N$21

Sheet Datos sitio
A1: Checklist para revisión heurística de usabilidad v.3beta | C1: 40756
A2: basada en la tesis de Mª del Carmen Suárez Torrente
A3: Sirius: Sistema de Evaluación de la Usabilidad Web Orientado al Usuario y basado en la Determinación de Tareas Críticas
A5: Autor: Olga Carreras Montoto | B5: (Usable y accesible)
A6: Mejoras de la v.3 por: Cecilio Sánchez «Cean» | B6: (leevel)
A7: Artículo: http://olgacarreras.blogspot.com/2011/07/sirius-nueva-sistema-para-la-evaluacion.html
A10: DATOS GENERALES DE LA EVALUACIÓN
A11: Evaluador | B11: GitHub Copilot
A12: Fecha de evaluación | B12: 46147
A13: Nombre del sitio evaluado | B13: Taxi Transfer Tenerife
A14: URL del sitio evaluado | B14: file:///index.html (prototipo local)
A15: Tipo de sitio evaluado | B15: Portal de Servicios | C15: (nota: no admite la definición de sitio híbrido, ver pp. 162 de la tesis)
A16: Navegador con el que se revisa | B16: Google Chrome
A17: Versión el navegador | B17: 124
A20: Cómo usar esta Excel
C21: http://olgacarreras.blogspot.com/2011/07/sirius-nueva-sistema-para-la-evaluacion.html
A22: 1. Se recomienda leer primero el artículo dónde se explica el nuevo sistema de evaluación Sirius:
A23: 2. Rellenar los datos generales del sitio a evaluar (en esta pestaña)
A24: 3. Evaluar los criterios de cada heurístico (10, uno por pestaña) según las indicaciones que se incluyen en cada pestaña
A25: 4. En la pestaña "Cálculo de % de usabilidad" se puede consultar la puntuación que recibe el sitio (pocentaje: 0-100) según la evaluación que se ha hecho de los diferentes criterios
A27: Licencia
A29: Esta excel se distribuye gratuitamente. Está protegida para evitar versiones erróneas.
A30: Si deseas colaborar en su mejora o reportar una sugerencia o incedencia puedes enviar un correo a: | C30: carreras.olga@gmail.com

Sheet 1, Aspectos generales
A1: CRITERIOS DEL "HEURÍSTICO ASPECTOS GENERALES": Elementos relacionados con los objetivos del sitio, el look & feel, coherencia y nivel de actualización de contenidos.
A2: Código | B2: Criterio | C2: Valor | D2: Relevancia | E2: Comentarios | F2: Valor interno(vc) | G2: Valor interno de relevancia (rc) | H2: Factor de corrección (fc) | I2: Valor parcial | J2: Valor parcial 2
A3: AG1 | B3: Objetivos del sitio web concretos y bien definidos | C3: 10 | D3: =IF(OR(TipoDeSitio="",C3="NA"),"",VLOOKUP(CONCATENATE(A3,": ",B3),Tabla621,MATCH(TipoDeSitio,Tipos,0)+1,0)) | E3: Los objetivos del servicio de traslados están claramente indicados en la landing. | F3: =IF(C3="","",VLOOKUP(C3,ValoresVC,2,0)) | G3: =IF(D3="","",VLOOKUP($D3,ValoresRC,2,0)) | H3: =IF(OR(G3="",G3=0,'Cálculo de % usabilidad'!$F$5=0),"",G3/'Cálculo de % usabilidad'!$F$5) | I3: =IF(OR(H3="",F3=""),"",H3*F3) | J3: =IF(H3="","",H3*10)
A4: AG2 | B4: Contenidos y servicios ofrecidos precisos y completos | C4: 10 | D4: =IF(OR(TipoDeSitio="",C4="NA"),"",VLOOKUP(CONCATENATE(A4,": ",B4),Tabla621,MATCH(TipoDeSitio,Tipos,0)+1,0)) | E4: Formulario de reserva, gestión y contacto cubren el flujo completo. | F4: =IF(C4="","",VLOOKUP(C4,ValoresVC,2,0)) | G4: =IF(D4="","",VLOOKUP($D4,ValoresRC,2,0)) | H4: =IF(OR(G4="",G4=0,'Cálculo de % usabilidad'!$F$5=0),"",G4/'Cálculo de % usabilidad'!$F$5) | I4: =IF(OR(H4="",F4=""),"",H4*F4) | J4: =IF(H4="","",H4*10)
A5: AG3 | B5: Estructura general del sitio web orientada al usuario | C5: 10 | D5: =IF(OR(TipoDeSitio="",C5="NA"),"",VLOOKUP(CONCATENATE(A5,": ",B5),Tabla621,MATCH(TipoDeSitio,Tipos,0)+1,0)) | E5: Menú global con 4 secciones lógicas: Inicio, Reservar, Mis Reservas, Contacto. | F5: =IF(C5="","",VLOOKUP(C5,ValoresVC,2,0)) | G5: =IF(D5="","",VLOOKUP($D5,ValoresRC,2,0)) | H5: =IF(OR(G5="",G5=0,'Cálculo de % usabilidad'!$F$5=0),"",G5/'Cálculo de % usabilidad'!$F$5) | I5: =IF(OR(H5="",F5=""),"",H5*F5) | J5: =IF(H5="","",H5*10)
A6: AG4 | B6: Look & Feel general se corresponde con los objetivos, características, contenidos y servicios del sitio web | C6: 10 | D6: =IF(OR(TipoDeSitio="",C6="NA"),"",VLOOKUP(CONCATENATE(A6,": ",B6),Tabla621,MATCH(TipoDeSitio,Tipos,0)+1,0)) | E6: Estética de transporte profesional con Bootstrap azul corporativo. | F6: =IF(C6="","",VLOOKUP(C6,ValoresVC,2,0)) | G6: =IF(D6="","",VLOOKUP($D6,ValoresRC,2,0)) | H6: =IF(OR(G6="",G6=0,'Cálculo de % usabilidad'!$F$5=0),"",G6/'Cálculo de % usabilidad'!$F$5) | I6: =IF(OR(H6="",F6=""),"",H6*F6) | J6: =IF(H6="","",H6*10)
A7: AG5 | B7: Diseño general del sitio web reconocible | C7: 10 | D7: =IF(OR(TipoDeSitio="",C7="NA"),"",VLOOKUP(CONCATENATE(A7,": ",B7),Tabla621,MATCH(TipoDeSitio,Tipos,0)+1,0)) | E7: Logo de taxi + nombre de marca visible en todas las páginas. | F7: =IF(C7="","",VLOOKUP(C7,ValoresVC,2,0)) | G7: =IF(D7="","",VLOOKUP($D7,ValoresRC,2,0)) | H7: =IF(OR(G7="",G7=0,'Cálculo de % usabilidad'!$F$5=0),"",G7/'Cálculo de % usabilidad'!$F$5) | I7: =IF(OR(H7="",F7=""),"",H7*F7) | J7: =IF(H7="","",H7*10)
A8: AG6 | B8: Diseño general del sitio web coherente | C8: 10 | D8: =IF(OR(TipoDeSitio="",C8="NA"),"",VLOOKUP(CONCATENATE(A8,": ",B8),Tabla621,MATCH(TipoDeSitio,Tipos,0)+1,0)) | E8: Navbar, tipografía y paleta de color consistentes en todas las páginas. | F8: =IF(C8="","",VLOOKUP(C8,ValoresVC,2,0)) | G8: =IF(D8="","",VLOOKUP($D8,ValoresRC,2,0)) | H8: =IF(OR(G8="",G8=0,'Cálculo de % usabilidad'!$F$5=0),"",G8/'Cálculo de % usabilidad'!$F$5) | I8: =IF(OR(H8="",F8=""),"",H8*F8) | J8: =IF(H8="","",H8*10)
A9: AG7 | B9: Se utiliza el idioma del usuario | C9: 10 | D9: =IF(OR(TipoDeSitio="",C9="NA"),"",VLOOKUP(CONCATENATE(A9,": ",B9),Tabla621,MATCH(TipoDeSitio,Tipos,0)+1,0)) | E9: Todo el contenido está en español. | F9: =IF(C9="","",VLOOKUP(C9,ValoresVC,2,0)) | G9: =IF(D9="","",VLOOKUP($D9,ValoresRC,2,0)) | H9: =IF(OR(G9="",G9=0,'Cálculo de % usabilidad'!$F$5=0),"",G9/'Cálculo de % usabilidad'!$F$5) | I9: =IF(OR(H9="",F9=""),"",H9*F9) | J9: =IF(H9="","",H9*10)
A10: AG8 | B10: Se da soporte a otro/s idioma/s | C10: 10 | D10: =IF(OR(TipoDeSitio="",C10="NA"),"",VLOOKUP(CONCATENATE(A10,": ",B10),Tabla621,MATCH(TipoDeSitio,Tipos,0)+1,0)) | E10: Botón de cambio de idioma (lang-toggle) en la barra de navegación. | F10: =IF(C10="","",VLOOKUP(C10,ValoresVC,2,0)) | G10: =IF(D10="","",VLOOKUP($D10,ValoresRC,2,0)) | H10: =IF(OR(G10="",G10=0,'Cálculo de % usabilidad'!$F$5=0),"",G10/'Cálculo de % usabilidad'!$F$5) | I10: =IF(OR(H10="",F10=""),"",H10*F10) | J10: =IF(H10="","",H10*10)
A11: AG9 | B11: Traducción del sitio completa y correcta | C11: 10 | D11: =IF(OR(TipoDeSitio="",C11="NA"),"",VLOOKUP(CONCATENATE(A11,": ",B11),Tabla621,MATCH(TipoDeSitio,Tipos,0)+1,0)) | E11: Todos los textos usan atributos data-i18n con traducciones completas. | F11: =IF(C11="","",VLOOKUP(C11,ValoresVC,2,0)) | G11: =IF(D11="","",VLOOKUP($D11,ValoresRC,2,0)) | H11: =IF(OR(G11="",G11=0,'Cálculo de % usabilidad'!$F$5=0),"",G11/'Cálculo de % usabilidad'!$F$5) | I11: =IF(OR(H11="",F11=""),"",H11*F11) | J11: =IF(H11="","",H11*10)
A12: AG10 | B12: Sitio web actualizado periódicamente | C12: NA | D12: =IF(OR(TipoDeSitio="",C12="NA"),"",VLOOKUP(CONCATENATE(A12,": ",B12),Tabla621,MATCH(TipoDeSitio,Tipos,0)+1,0)) | E12: Es un prototipo estático; no hay historial de actualizaciones. | F12: =IF(C12="","",VLOOKUP(C12,ValoresVC,2,0)) | G12: =IF(D12="","",VLOOKUP($D12,ValoresRC,2,0)) | H12: =IF(OR(G12="",G12=0,'Cálculo de % usabilidad'!$F$5=0),"",G12/'Cálculo de % usabilidad'!$F$5) | I12: =IF(OR(H12="",F12=""),"",H12*F12) | J12: =IF(H12="","",H12*10) | K12: Núm.elementos evaluados | L12: =10-(COUNTIF(C3:C12,"NA")+COUNTBLANK(C3:C12)) | M12: (no contabiliza ni los vacíos ni los NA)
G13: =IF(SUM(G3:G12)=0,"",SUM(G3:G12))
A14: Instrucciones | C14: Leyenda Valor
A15: 1. Evalue cada criterio y rellene la columna "Valor" según la leyenda | C15: 0 | D15: No se cumple en absoluto | F15: NEP | G15: No se cumple en los enlaces principales
A16: 2. Añada sus comentarios o la referencia a los mismos en otro documento anexo en la columna "Comentarios" | C16: 10 | D16: Se cumple totalmente | F16: NPP | G16: No se cumple en la página principal
C17: NA | D17: Criterio no aplicable en el sitio | F17: NPI | G17: No se cumple en alguna página interior
C18: NTS | D18: No se cumple en todo el sitio | F18: S | G18: Se cumple el criterio

Sheet 2, Identidad e Información
A1: CRITERIOS DEL "IDENTIDAD E INFORMACIÓN": Elementos relacionados con la identidad del sitio, la información proporcionada sobre el proveedor y la autoría de los contenidos.
A2: Código | B2: Criterio | C2: Valor | D2: Relevancia | E2: Comentarios | F2: Valor interno(vc) | G2: Valor interno de relevancia (rc) | H2: Factor de corrección (fc) | I2: Valor parcial | J2: Valor parcial 2
A3: II.1 | B3: Identidad o logotipo significativo, identificable y suficientemente visible | C3: 10 | D3: =IF(OR(TipoDeSitio="",C3="NA"),"",VLOOKUP(CONCATENATE(A3,": ",B3),Tabla622,MATCH(TipoDeSitio,Tipos,0)+1,0)) | E3: Logo SVG de taxi + nombre "Taxi Transfer Tenerife" en la barra superior. | F3: =IF(C3="","",VLOOKUP(C3,ValoresVC,2,0)) | G3: =IF(D3="","",VLOOKUP($D3,ValoresRC,2,0)) | H3: =IF(OR(G3="",G3=0,'Cálculo de % usabilidad'!$F$5=0),"",G3/'Cálculo de % usabilidad'!$F$5) | I3: =IF(OR(H3="",F3=""),"",H3*F3) | J3: =IF(H3="","",H3*10)
A4: II.2 | B4: Identidad del sitio en todas las páginas | C4: 10 | D4: =IF(OR(TipoDeSitio="",C4="NA"),"",VLOOKUP(CONCATENATE(A4,": ",B4),Tabla622,MATCH(TipoDeSitio,Tipos,0)+1,0)) | E4: Navbar fija con logo y nombre en todas las páginas. | F4: =IF(C4="","",VLOOKUP(C4,ValoresVC,2,0)) | G4: =IF(D4="","",VLOOKUP($D4,ValoresRC,2,0)) | H4: =IF(OR(G4="",G4=0,'Cálculo de % usabilidad'!$F$5=0),"",G4/'Cálculo de % usabilidad'!$F$5) | I4: =IF(OR(H4="",F4=""),"",H4*F4) | J4: =IF(H4="","",H4*10)
A5: II.3 | B5: Eslogan o tagline adecuado al objetivo del sitio | C5: 10 | D5: =IF(OR(TipoDeSitio="",C5="NA"),"",VLOOKUP(CONCATENATE(A5,": ",B5),Tabla622,MATCH(TipoDeSitio,Tipos,0)+1,0)) | E5: "Traslados desde el Aeropuerto de Tenerife Sur" en la sección hero. | F5: =IF(C5="","",VLOOKUP(C5,ValoresVC,2,0)) | G5: =IF(D5="","",VLOOKUP($D5,ValoresRC,2,0)) | H5: =IF(OR(G5="",G5=0,'Cálculo de % usabilidad'!$F$5=0),"",G5/'Cálculo de % usabilidad'!$F$5) | I5: =IF(OR(H5="",F5=""),"",H5*F5) | J5: =IF(H5="","",H5*10)
A6: II.4 | B6: Se ofrece información sobre el sitio web, empresa | C6: 8 | D6: =IF(OR(TipoDeSitio="",C6="NA"),"",VLOOKUP(CONCATENATE(A6,": ",B6),Tabla622,MATCH(TipoDeSitio,Tipos,0)+1,0)) | E6: Página de contacto incluye dirección, teléfono y email corporativo. | F6: =IF(C6="","",VLOOKUP(C6,ValoresVC,2,0)) | G6: =IF(D6="","",VLOOKUP($D6,ValoresRC,2,0)) | H6: =IF(OR(G6="",G6=0,'Cálculo de % usabilidad'!$F$5=0),"",G6/'Cálculo de % usabilidad'!$F$5) | I6: =IF(OR(H6="",F6=""),"",H6*F6) | J6: =IF(H6="","",H6*10)
A7: II.5 | B7: Existen mecanismos de contacto | C7: 10 | D7: =IF(OR(TipoDeSitio="",C7="NA"),"",VLOOKUP(CONCATENATE(A7,": ",B7),Tabla622,MATCH(TipoDeSitio,Tipos,0)+1,0)) | E7: Página de contacto con formulario, tel: y mailto: clicables. | F7: =IF(C7="","",VLOOKUP(C7,ValoresVC,2,0)) | G7: =IF(D7="","",VLOOKUP($D7,ValoresRC,2,0)) | H7: =IF(OR(G7="",G7=0,'Cálculo de % usabilidad'!$F$5=0),"",G7/'Cálculo de % usabilidad'!$F$5) | I7: =IF(OR(H7="",F7=""),"",H7*F7) | J7: =IF(H7="","",H7*10)
A8: II.6 | B8: Se ofrece información sobre la protección de datos de carácter personal o los derechos de autor de los contenidos del sitio web | C8: 0 | D8: =IF(OR(TipoDeSitio="",C8="NA"),"",VLOOKUP(CONCATENATE(A8,": ",B8),Tabla622,MATCH(TipoDeSitio,Tipos,0)+1,0)) | E8: No existe enlace a Política de Privacidad ni aviso legal. | F8: =IF(C8="","",VLOOKUP(C8,ValoresVC,2,0)) | G8: =IF(D8="","",VLOOKUP($D8,ValoresRC,2,0)) | H8: =IF(OR(G8="",G8=0,'Cálculo de % usabilidad'!$F$5=0),"",G8/'Cálculo de % usabilidad'!$F$5) | I8: =IF(OR(H8="",F8=""),"",H8*F8) | J8: =IF(H8="","",H8*10)
A9: II.7 | B9: Se ofrece información sobre el autor, fuentes y fechas de creación y revisión en artículos, noticias, informes | C9: NA | D9: =IF(OR(TipoDeSitio="",C9="NA"),"",VLOOKUP(CONCATENATE(A9,": ",B9),Tabla622,MATCH(TipoDeSitio,Tipos,0)+1,0)) | E9: El sitio no publica artículos ni noticias. | F9: =IF(C9="","",VLOOKUP(C9,ValoresVC,2,0)) | G9: =IF(D9="","",VLOOKUP($D9,ValoresRC,2,0)) | H9: =IF(OR(G9="",G9=0,'Cálculo de % usabilidad'!$F$5=0),"",G9/'Cálculo de % usabilidad'!$F$5) | I9: =IF(OR(H9="",F9=""),"",H9*F9) | J9: =IF(H9="","",H9*10) | K9: Núm.elementos evaluados | L9: =7-(COUNTIF(C3:C9,"NA")+COUNTBLANK(C3:C9)) | M9: (no contabiliza ni los vacíos ni los NA)
G10: =IF(SUM(G3:G9)=0,"",SUM(G3:G9))
A11: Instrucciones | C11: Leyenda Valor
A12: 1. Evalue cada criterio y rellene la columna "Valor" según la leyenda | C12: 0 | D12: No se cumple en absoluto | F12: NEP | G12: No se cumple en los enlaces principales
A13: 2. Añada sus comentarios o la referencia a los mismos en otro documento anexo en la columna "Comentarios" | C13: 10 | D13: Se cumple totalmente | F13: NPP | G13: No se cumple en la página principal
C14: NA | D14: Criterio no aplicable en el sitio | F14: NPI | G14: No se cumple en alguna página interior
C15: NTS | D15: No se cumple en todo el sitio | F15: S | G15: Se cumple el criterio

Sheet 3, Estructura y navegación
A1: CRITERIOS DEL "ESTRUCTURA Y NAVEGACIÓN": Elementos relacionados con la idoneidad de la arquitectura de la información y la navegación del sitio.
A2: Código | B2: Criterio | C2: Valor | D2: Relevancia | E2: Comentarios | F2: Valor interno(vc) | G2: Valor interno de relevancia (rc) | H2: Factor de corrección (fc) | I2: Valor parcial | J2: Valor parcial 2
A3: EN.1 | B3: Se ha evitado pantalla de bienvenida | C3: 10 | D3: =IF(OR(TipoDeSitio="",C3="NA"),"",VLOOKUP(CONCATENATE(A3,": ",B3),Tabla623,MATCH(TipoDeSitio,Tipos,0)+1,0)) | E3: El sitio abre directamente en la landing sin pantalla intermedia. | F3: =IF(C3="","",VLOOKUP(C3,ValoresVC,2,0)) | G3: =IF(D3="","",VLOOKUP($D3,ValoresRC,2,0)) | H3: =IF(OR(G3="",G3=0,'Cálculo de % usabilidad'!$F$5=0),"",G3/'Cálculo de % usabilidad'!$F$5) | I3: =IF(OR(H3="",F3=""),"",H3*F3) | J3: =IF(H3="","",H3*10)
A4: EN.2 | B4: Estructura de organización y navegación adecuada | C4: 10 | D4: =IF(OR(TipoDeSitio="",C4="NA"),"",VLOOKUP(CONCATENATE(A4,": ",B4),Tabla623,MATCH(TipoDeSitio,Tipos,0)+1,0)) | E4: Flujo lineal: inicio → reserva → confirmación → pago → gestión. | F4: =IF(C4="","",VLOOKUP(C4,ValoresVC,2,0)) | G4: =IF(D4="","",VLOOKUP($D4,ValoresRC,2,0)) | H4: =IF(OR(G4="",G4=0,'Cálculo de % usabilidad'!$F$5=0),"",G4/'Cálculo de % usabilidad'!$F$5) | I4: =IF(OR(H4="",F4=""),"",H4*F4) | J4: =IF(H4="","",H4*10)
A5: EN.3 | B5: Organización de elementos consistente con las convenciones | C5: 10 | D5: =IF(OR(TipoDeSitio="",C5="NA"),"",VLOOKUP(CONCATENATE(A5,": ",B5),Tabla623,MATCH(TipoDeSitio,Tipos,0)+1,0)) | E5: Navbar fija con convención estándar Bootstrap en la parte superior. | F5: =IF(C5="","",VLOOKUP(C5,ValoresVC,2,0)) | G5: =IF(D5="","",VLOOKUP($D5,ValoresRC,2,0)) | H5: =IF(OR(G5="",G5=0,'Cálculo de % usabilidad'!$F$5=0),"",G5/'Cálculo de % usabilidad'!$F$5) | I5: =IF(OR(H5="",F5=""),"",H5*F5) | J5: =IF(H5="","",H5*10)
A6: EN.4 | B6: Control del número de elementos y de términos por elemento en los menús de navegación | C6: 10 | D6: =IF(OR(TipoDeSitio="",C6="NA"),"",VLOOKUP(CONCATENATE(A6,": ",B6),Tabla623,MATCH(TipoDeSitio,Tipos,0)+1,0)) | E6: Menú con exactamente 4 elementos: Inicio, Reservar, Mis Reservas, Contacto. | F6: =IF(C6="","",VLOOKUP(C6,ValoresVC,2,0)) | G6: =IF(D6="","",VLOOKUP($D6,ValoresRC,2,0)) | H6: =IF(OR(G6="",G6=0,'Cálculo de % usabilidad'!$F$5=0),"",G6/'Cálculo de % usabilidad'!$F$5) | I6: =IF(OR(H6="",F6=""),"",H6*F6) | J6: =IF(H6="","",H6*10)
A7: EN.5 | B7: Equilibrio entre profundidad y anchura en el caso de estructura jerárquica | C7: 10 | D7: =IF(OR(TipoDeSitio="",C7="NA"),"",VLOOKUP(CONCATENATE(A7,": ",B7),Tabla623,MATCH(TipoDeSitio,Tipos,0)+1,0)) | E7: Jerarquía de un nivel de profundidad; todos los destinos accesibles desde la landing. | F7: =IF(C7="","",VLOOKUP(C7,ValoresVC,2,0)) | G7: =IF(D7="","",VLOOKUP($D7,ValoresRC,2,0)) | H7: =IF(OR(G7="",G7=0,'Cálculo de % usabilidad'!$F$5=0),"",G7/'Cálculo de % usabilidad'!$F$5) | I7: =IF(OR(H7="",F7=""),"",H7*F7) | J7: =IF(H7="","",H7*10)
A8: EN.6 | B8: Enlaces fácilmente reconocibles como tales | C8: 10 | D8: =IF(OR(TipoDeSitio="",C8="NA"),"",VLOOKUP(CONCATENATE(A8,": ",B8),Tabla623,MATCH(TipoDeSitio,Tipos,0)+1,0)) | E8: Los enlaces de navegación son texto azul subrayado y botones Bootstrap estándar. | F8: =IF(C8="","",VLOOKUP(C8,ValoresVC,2,0)) | G8: =IF(D8="","",VLOOKUP($D8,ValoresRC,2,0)) | H8: =IF(OR(G8="",G8=0,'Cálculo de % usabilidad'!$F$5=0),"",G8/'Cálculo de % usabilidad'!$F$5) | I8: =IF(OR(H8="",F8=""),"",H8*F8) | J8: =IF(H8="","",H8*10)
A9: EN.7 | B9: La caracterización de los enlaces indica su estado (visitados, activos) | C9: 10 | D9: =IF(OR(TipoDeSitio="",C9="NA"),"",VLOOKUP(CONCATENATE(A9,": ",B9),Tabla623,MATCH(TipoDeSitio,Tipos,0)+1,0)) | E9: Atributo aria-current="page" y clase CSS "active" en el ítem actual del menú. | F9: =IF(C9="","",VLOOKUP(C9,ValoresVC,2,0)) | G9: =IF(D9="","",VLOOKUP($D9,ValoresRC,2,0)) | H9: =IF(OR(G9="",G9=0,'Cálculo de % usabilidad'!$F$5=0),"",G9/'Cálculo de % usabilidad'!$F$5) | I9: =IF(OR(H9="",F9=""),"",H9*F9) | J9: =IF(H9="","",H9*10)
A10: EN.8 | B10: No hay redundancia de enlaces | C10: 10 | D10: =IF(OR(TipoDeSitio="",C10="NA"),"",VLOOKUP(CONCATENATE(A10,": ",B10),Tabla623,MATCH(TipoDeSitio,Tipos,0)+1,0)) | E10: No existen duplicidades de enlace dentro de los menús de navegación. | F10: =IF(C10="","",VLOOKUP(C10,ValoresVC,2,0)) | G10: =IF(D10="","",VLOOKUP($D10,ValoresRC,2,0)) | H10: =IF(OR(G10="",G10=0,'Cálculo de % usabilidad'!$F$5=0),"",G10/'Cálculo de % usabilidad'!$F$5) | I10: =IF(OR(H10="",F10=""),"",H10*F10) | J10: =IF(H10="","",H10*10)
A11: EN.9 | B11: No hay enlaces rotos | C11: 10 | D11: =IF(OR(TipoDeSitio="",C11="NA"),"",VLOOKUP(CONCATENATE(A11,": ",B11),Tabla623,MATCH(TipoDeSitio,Tipos,0)+1,0)) | E11: Todos los href apuntan a páginas existentes dentro del prototipo. | F11: =IF(C11="","",VLOOKUP(C11,ValoresVC,2,0)) | G11: =IF(D11="","",VLOOKUP($D11,ValoresRC,2,0)) | H11: =IF(OR(G11="",G11=0,'Cálculo de % usabilidad'!$F$5=0),"",G11/'Cálculo de % usabilidad'!$F$5) | I11: =IF(OR(H11="",F11=""),"",H11*F11) | J11: =IF(H11="","",H11*10)
A12: EN.10 | B12: No hay enlaces que lleven a la misma página que se está visualizando | C12: 10 | D12: =IF(OR(TipoDeSitio="",C12="NA"),"",VLOOKUP(CONCATENATE(A12,": ",B12),Tabla623,MATCH(TipoDeSitio,Tipos,0)+1,0)) | E12: La página activa no tiene enlace a sí misma (marcada como activa). | F12: =IF(C12="","",VLOOKUP(C12,ValoresVC,2,0)) | G12: =IF(D12="","",VLOOKUP($D12,ValoresRC,2,0)) | H12: =IF(OR(G12="",G12=0,'Cálculo de % usabilidad'!$F$5=0),"",G12/'Cálculo de % usabilidad'!$F$5) | I12: =IF(OR(H12="",F12=""),"",H12*F12) | J12: =IF(H12="","",H12*10)
A13: EN.11 | B13: En las imágenes de enlace se indica el contenido al que se va a acceder | C13: 10 | D13: =IF(OR(TipoDeSitio="",C13="NA"),"",VLOOKUP(CONCATENATE(A13,": ",B13),Tabla623,MATCH(TipoDeSitio,Tipos,0)+1,0)) | E13: Logo SVG tiene alt="Taxi logo"; tarjetas de destino tienen aria-label descriptivo. | F13: =IF(C13="","",VLOOKUP(C13,ValoresVC,2,0)) | G13: =IF(D13="","",VLOOKUP($D13,ValoresRC,2,0)) | H13: =IF(OR(G13="",G13=0,'Cálculo de % usabilidad'!$F$5=0),"",G13/'Cálculo de % usabilidad'!$F$5) | I13: =IF(OR(H13="",F13=""),"",H13*F13) | J13: =IF(H13="","",H13*10)
A14: EN.12 | B14: Existe un enlace para volver al inicio en cada página | C14: 10 | D14: =IF(OR(TipoDeSitio="",C14="NA"),"",VLOOKUP(CONCATENATE(A14,": ",B14),Tabla623,MATCH(TipoDeSitio,Tipos,0)+1,0)) | E14: El logotipo y el enlace de marca apuntan siempre a index.html. | F14: =IF(C14="","",VLOOKUP(C14,ValoresVC,2,0)) | G14: =IF(D14="","",VLOOKUP($D14,ValoresRC,2,0)) | H14: =IF(OR(G14="",G14=0,'Cálculo de % usabilidad'!$F$5=0),"",G14/'Cálculo de % usabilidad'!$F$5) | I14: =IF(OR(H14="",F14=""),"",H14*F14) | J14: =IF(H14="","",H14*10)
A15: EN.13 | B15: Existen elementos de navegación que orienten al usuario acerca de dónde está y cómo deshacer su navegación (ej: migas) | C15: 5 | D15: =IF(OR(TipoDeSitio="",C15="NA"),"",VLOOKUP(CONCATENATE(A15,": ",B15),Tabla623,MATCH(TipoDeSitio,Tipos,0)+1,0)) | E15: El menú marca la página activa con aria-current y clase CSS "active", pero no hay migas de pan (breadcrumbs) explícitas. | F15: =IF(C15="","",VLOOKUP(C15,ValoresVC,2,0)) | G15: =IF(D15="","",VLOOKUP($D15,ValoresRC,2,0)) | H15: =IF(OR(G15="",G15=0,'Cálculo de % usabilidad'!$F$5=0),"",G15/'Cálculo de % usabilidad'!$F$5) | I15: =IF(OR(H15="",F15=""),"",H15*F15) | J15: =IF(H15="","",H15*10)
A16: EN.14 | B16: Existe mapa del sitio para acceder directamente a los contenidos sin navegar | C16: 0 | D16: =IF(OR(TipoDeSitio="",C16="NA"),"",VLOOKUP(CONCATENATE(A16,": ",B16),Tabla623,MATCH(TipoDeSitio,Tipos,0)+1,0)) | E16: No existe mapa del sitio. El sitio tiene solo 4 páginas por lo que su necesidad es baja, pero no está implementado. | F16: =IF(C16="","",VLOOKUP(C16,ValoresVC,2,0)) | G16: =IF(D16="","",VLOOKUP($D16,ValoresRC,2,0)) | H16: =IF(OR(G16="",G16=0,'Cálculo de % usabilidad'!$F$5=0),"",G16/'Cálculo de % usabilidad'!$F$5) | I16: =IF(OR(H16="",F16=""),"",H16*F16) | J16: =IF(H16="","",H16*10) | K16: Núm.elementos evaluados | L16: =14-(COUNTIF(C3:C16,"NA")+COUNTBLANK(C3:C16)) | M16: (no contabiliza ni los vacíos ni los NA)
G17: =IF(SUM(G3:G16)=0,"",SUM(G3:G16))
A18: Instrucciones | C18: Leyenda Valor
A19: 1. Evalue cada criterio y rellene la columna "Valor" según la leyenda | C19: 0 | D19: No se cumple en absoluto | F19: NEP | G19: No se cumple en los enlaces principales
A20: 2. Añada sus comentarios o la referencia a los mismos en otro documento anexo en la columna "Comentarios" | C20: 10 | D20: Se cumple totalmente | F20: NPP | G20: No se cumple en la página principal
C21: NA | D21: Criterio no aplicable en el sitio | F21: NPI | G21: No se cumple en alguna página interior
C22: NTS | D22: No se cumple en todo el sitio | F22: S | G22: Se cumple el criterio

Sheet 4, Rotulado
A1: CRITERIOS DEL "ROTULADO": Elementos relacionados con la significación, corrección y familiaridad del rotulado de los contenidos.
A2: Código | B2: Criterio | C2: Valor | D2: Relevancia | E2: Comentarios | F2: Valor interno(vc) | G2: Valor interno de relevancia (rc) | H2: Factor de corrección (fc) | I2: Valor parcial | J2: Valor parcial 2
A3: RO.1 | B3: Rótulos significativos | C3: 10 | D3: =IF(OR(TipoDeSitio="",C3="NA"),"",VLOOKUP(CONCATENATE(A3,": ",B3),Tabla624,MATCH(TipoDeSitio,Tipos,0)+1,0)) | E3: Los rótulos de sección (Reservar, Mis Reservas, Contacto) son autoexplicativos. | F3: =IF(C3="","",VLOOKUP(C3,ValoresVC,2,0)) | G3: =IF(D3="","",VLOOKUP($D3,ValoresRC,2,0)) | H3: =IF(OR(G3="",G3=0,'Cálculo de % usabilidad'!$F$5=0),"",G3/'Cálculo de % usabilidad'!$F$5) | I3: =IF(OR(H3="",F3=""),"",H3*F3) | J3: =IF(H3="","",H3*10)
A4: RO.2 | B4: Sistema de rotulado controlado y preciso | C4: 10 | D4: =IF(OR(TipoDeSitio="",C4="NA"),"",VLOOKUP(CONCATENATE(A4,": ",B4),Tabla624,MATCH(TipoDeSitio,Tipos,0)+1,0)) | E4: Nomenclatura coherente en etiquetas de formulario y navegación. | F4: =IF(C4="","",VLOOKUP(C4,ValoresVC,2,0)) | G4: =IF(D4="","",VLOOKUP($D4,ValoresRC,2,0)) | H4: =IF(OR(G4="",G4=0,'Cálculo de % usabilidad'!$F$5=0),"",G4/'Cálculo de % usabilidad'!$F$5) | I4: =IF(OR(H4="",F4=""),"",H4*F4) | J4: =IF(H4="","",H4*10)
A5: RO.3 | B5: Título de las páginas, correcto y planificado | C5: 10 | D5: =IF(OR(TipoDeSitio="",C5="NA"),"",VLOOKUP(CONCATENATE(A5,": ",B5),Tabla624,MATCH(TipoDeSitio,Tipos,0)+1,0)) | E5: Cada página tiene <title> específico: "Reserva tu Traslado", "Contacto", etc. | F5: =IF(C5="","",VLOOKUP(C5,ValoresVC,2,0)) | G5: =IF(D5="","",VLOOKUP($D5,ValoresRC,2,0)) | H5: =IF(OR(G5="",G5=0,'Cálculo de % usabilidad'!$F$5=0),"",G5/'Cálculo de % usabilidad'!$F$5) | I5: =IF(OR(H5="",F5=""),"",H5*F5) | J5: =IF(H5="","",H5*10)
A6: RO.4 | B6: URL página principal correcta, clara y fácil de recordar | C6: NA | D6: =IF(OR(TipoDeSitio="",C6="NA"),"",VLOOKUP(CONCATENATE(A6,": ",B6),Tabla624,MATCH(TipoDeSitio,Tipos,0)+1,0)) | E6: Es un prototipo local sin URL pública. | F6: =IF(C6="","",VLOOKUP(C6,ValoresVC,2,0)) | G6: =IF(D6="","",VLOOKUP($D6,ValoresRC,2,0)) | H6: =IF(OR(G6="",G6=0,'Cálculo de % usabilidad'!$F$5=0),"",G6/'Cálculo de % usabilidad'!$F$5) | I6: =IF(OR(H6="",F6=""),"",H6*F6) | J6: =IF(H6="","",H6*10)
A7: RO.5 | B7: URLs de páginas internas claras | C7: 10 | D7: =IF(OR(TipoDeSitio="",C7="NA"),"",VLOOKUP(CONCATENATE(A7,": ",B7),Tabla624,MATCH(TipoDeSitio,Tipos,0)+1,0)) | E7: Archivos: booking.html, manage-booking.html, contact.html, payment.html. | F7: =IF(C7="","",VLOOKUP(C7,ValoresVC,2,0)) | G7: =IF(D7="","",VLOOKUP($D7,ValoresRC,2,0)) | H7: =IF(OR(G7="",G7=0,'Cálculo de % usabilidad'!$F$5=0),"",G7/'Cálculo de % usabilidad'!$F$5) | I7: =IF(OR(H7="",F7=""),"",H7*F7) | J7: =IF(H7="","",H7*10)
A8: RO.6 | B8: URLs de páginas internas permanentes | C8: NA | D8: =IF(OR(TipoDeSitio="",C8="NA"),"",VLOOKUP(CONCATENATE(A8,": ",B8),Tabla624,MATCH(TipoDeSitio,Tipos,0)+1,0)) | E8: Prototipo estático sin URLs de producción. | F8: =IF(C8="","",VLOOKUP(C8,ValoresVC,2,0)) | G8: =IF(D8="","",VLOOKUP($D8,ValoresRC,2,0)) | H8: =IF(OR(G8="",G8=0,'Cálculo de % usabilidad'!$F$5=0),"",G8/'Cálculo de % usabilidad'!$F$5) | I8: =IF(OR(H8="",F8=""),"",H8*F8) | J8: =IF(H8="","",H8*10) | K8: Núm.elementos evaluados | L8: =6-(COUNTIF(C3:C8,"NA")+COUNTBLANK(C3:C8)) | M8: (no contabiliza ni los vacíos ni los NA)
G9: =IF(SUM(G3:G8)=0,"",SUM(G3:G8))
A10: Instrucciones | C10: Leyenda Valor
A11: 1. Evalue cada criterio y rellene la columna "Valor" según la leyenda | C11: 0 | D11: No se cumple en absoluto | F11: NEP | G11: No se cumple en los enlaces principales
A12: 2. Añada sus comentarios o la referencia a los mismos en otro documento anexo en la columna "Comentarios" | C12: 10 | D12: Se cumple totalmente | F12: NPP | G12: No se cumple en la página principal
C13: NA | D13: Criterio no aplicable en el sitio | F13: NPI | G13: No se cumple en alguna página interior
C14: NTS | D14: No se cumple en todo el sitio | F14: S | G14: Se cumple el criterio

Sheet 5, Layout de la página
A1: CRITERIOS DEL "LAYOUT DE LA PÁGINA": Elementos relacionados con la distribución y el aspecto de los elementos de navegación e información en la interfaz
A2: Código | B2: Criterio | C2: Valor | D2: Relevancia | E2: Comentarios | F2: Valor interno(vc) | G2: Valor interno de relevancia (rc) | H2: Factor de corrección (fc) | I2: Valor parcial | J2: Valor parcial 2
A3: LA.1 | B3: Se aprovechan las zonas de alta jerarquía informativa de la página para contenidos de mayor relevancia | C3: 10 | D3: =IF(OR(TipoDeSitio="",C3="NA"),"",VLOOKUP(CONCATENATE(A3,": ",B3),Tabla625,MATCH(TipoDeSitio,Tipos,0)+1,0)) | E3: Hero section en la zona superior con CTA principal y título h1. | F3: =IF(C3="","",VLOOKUP(C3,ValoresVC,2,0)) | G3: =IF(D3="","",VLOOKUP($D3,ValoresRC,2,0)) | H3: =IF(OR(G3="",G3=0,'Cálculo de % usabilidad'!$F$5=0),"",G3/'Cálculo de % usabilidad'!$F$5) | I3: =IF(OR(H3="",F3=""),"",H3*F3) | J3: =IF(H3="","",H3*10)
A4: LA.2 | B4: Se ha evitado la sobrecarga informativa | C4: 10 | D4: =IF(OR(TipoDeSitio="",C4="NA"),"",VLOOKUP(CONCATENATE(A4,": ",B4),Tabla625,MATCH(TipoDeSitio,Tipos,0)+1,0)) | E4: Cada sección contiene un único tema; no hay acumulación de elementos. | F4: =IF(C4="","",VLOOKUP(C4,ValoresVC,2,0)) | G4: =IF(D4="","",VLOOKUP($D4,ValoresRC,2,0)) | H4: =IF(OR(G4="",G4=0,'Cálculo de % usabilidad'!$F$5=0),"",G4/'Cálculo de % usabilidad'!$F$5) | I4: =IF(OR(H4="",F4=""),"",H4*F4) | J4: =IF(H4="","",H4*10)
A5: LA.3 | B5: Es una interfaz limpia, sin ruido visual | C5: 10 | D5: =IF(OR(TipoDeSitio="",C5="NA"),"",VLOOKUP(CONCATENATE(A5,": ",B5),Tabla625,MATCH(TipoDeSitio,Tipos,0)+1,0)) | E5: Bootstrap 5 garantiza layout limpio con separación visual clara. | F5: =IF(C5="","",VLOOKUP(C5,ValoresVC,2,0)) | G5: =IF(D5="","",VLOOKUP($D5,ValoresRC,2,0)) | H5: =IF(OR(G5="",G5=0,'Cálculo de % usabilidad'!$F$5=0),"",G5/'Cálculo de % usabilidad'!$F$5) | I5: =IF(OR(H5="",F5=""),"",H5*F5) | J5: =IF(H5="","",H5*10)
A6: LA.4 | B6: Existen zonas en blanco entre los objetos informativos de la página para poder descansar la vista | C6: 10 | D6: =IF(OR(TipoDeSitio="",C6="NA"),"",VLOOKUP(CONCATENATE(A6,": ",B6),Tabla625,MATCH(TipoDeSitio,Tipos,0)+1,0)) | E6: Uso sistemático de py-5, mb-4, gap-3 para espaciado entre bloques. | F6: =IF(C6="","",VLOOKUP(C6,ValoresVC,2,0)) | G6: =IF(D6="","",VLOOKUP($D6,ValoresRC,2,0)) | H6: =IF(OR(G6="",G6=0,'Cálculo de % usabilidad'!$F$5=0),"",G6/'Cálculo de % usabilidad'!$F$5) | I6: =IF(OR(H6="",F6=""),"",H6*F6) | J6: =IF(H6="","",H6*10)
A7: LA.5 | B7: Uso correcto del espacio visual de la página | C7: 10 | D7: =IF(OR(TipoDeSitio="",C7="NA"),"",VLOOKUP(CONCATENATE(A7,": ",B7),Tabla625,MATCH(TipoDeSitio,Tipos,0)+1,0)) | E7: Grid de 12 columnas Bootstrap con ocupación equilibrada del espacio. | F7: =IF(C7="","",VLOOKUP(C7,ValoresVC,2,0)) | G7: =IF(D7="","",VLOOKUP($D7,ValoresRC,2,0)) | H7: =IF(OR(G7="",G7=0,'Cálculo de % usabilidad'!$F$5=0),"",G7/'Cálculo de % usabilidad'!$F$5) | I7: =IF(OR(H7="",F7=""),"",H7*F7) | J7: =IF(H7="","",H7*10)
A8: LA.6 | B8: Se utiliza correctamente la jerarquía visual para expresar las relaciones del tipo "parte de" entre los elementos de la página | C8: 10 | D8: =IF(OR(TipoDeSitio="",C8="NA"),"",VLOOKUP(CONCATENATE(A8,": ",B8),Tabla625,MATCH(TipoDeSitio,Tipos,0)+1,0)) | E8: Encabezados h1→h2→h3 bien jerarquizados; fieldsets en el formulario. | F8: =IF(C8="","",VLOOKUP(C8,ValoresVC,2,0)) | G8: =IF(D8="","",VLOOKUP($D8,ValoresRC,2,0)) | H8: =IF(OR(G8="",G8=0,'Cálculo de % usabilidad'!$F$5=0),"",G8/'Cálculo de % usabilidad'!$F$5) | I8: =IF(OR(H8="",F8=""),"",H8*F8) | J8: =IF(H8="","",H8*10)
A9: LA.7 | B9: Se ha controlado la longitud de página | C9: 10 | D9: =IF(OR(TipoDeSitio="",C9="NA"),"",VLOOKUP(CONCATENATE(A9,": ",B9),Tabla625,MATCH(TipoDeSitio,Tipos,0)+1,0)) | E9: Las páginas no superan 2-3 pantallas de scroll. | F9: =IF(C9="","",VLOOKUP(C9,ValoresVC,2,0)) | G9: =IF(D9="","",VLOOKUP($D9,ValoresRC,2,0)) | H9: =IF(OR(G9="",G9=0,'Cálculo de % usabilidad'!$F$5=0),"",G9/'Cálculo de % usabilidad'!$F$5) | I9: =IF(OR(H9="",F9=""),"",H9*F9) | J9: =IF(H9="","",H9*10)
A10: LA.8 | B10: La versión impresa de la página es correcta | C10: NA | D10: =IF(OR(TipoDeSitio="",C10="NA"),"",VLOOKUP(CONCATENATE(A10,": ",B10),Tabla625,MATCH(TipoDeSitio,Tipos,0)+1,0)) | E10: No aplica para este prototipo de revisión heurística. | F10: =IF(C10="","",VLOOKUP(C10,ValoresVC,2,0)) | G10: =IF(D10="","",VLOOKUP($D10,ValoresRC,2,0)) | H10: =IF(OR(G10="",G10=0,'Cálculo de % usabilidad'!$F$5=0),"",G10/'Cálculo de % usabilidad'!$F$5) | I10: =IF(OR(H10="",F10=""),"",H10*F10) | J10: =IF(H10="","",H10*10)
A11: LA.9 | B11: El texto de la página se lee sin dificultad | C11: 10 | D11: =IF(OR(TipoDeSitio="",C11="NA"),"",VLOOKUP(CONCATENATE(A11,": ",B11),Tabla625,MATCH(TipoDeSitio,Tipos,0)+1,0)) | E11: Texto en negro sobre fondo blanco/gris claro; contraste adecuado. | F11: =IF(C11="","",VLOOKUP(C11,ValoresVC,2,0)) | G11: =IF(D11="","",VLOOKUP($D11,ValoresRC,2,0)) | H11: =IF(OR(G11="",G11=0,'Cálculo de % usabilidad'!$F$5=0),"",G11/'Cálculo de % usabilidad'!$F$5) | I11: =IF(OR(H11="",F11=""),"",H11*F11) | J11: =IF(H11="","",H11*10)
A12: LA.10 | B12: Se ha evitado el texto parpadeante / deslizante | C12: 10 | D12: =IF(OR(TipoDeSitio="",C12="NA"),"",VLOOKUP(CONCATENATE(A12,": ",B12),Tabla625,MATCH(TipoDeSitio,Tipos,0)+1,0)) | E12: No se usan elementos <blink>, marquee ni animaciones CSS cíclicas. | F12: =IF(C12="","",VLOOKUP(C12,ValoresVC,2,0)) | G12: =IF(D12="","",VLOOKUP($D12,ValoresRC,2,0)) | H12: =IF(OR(G12="",G12=0,'Cálculo de % usabilidad'!$F$5=0),"",G12/'Cálculo de % usabilidad'!$F$5) | I12: =IF(OR(H12="",F12=""),"",H12*F12) | J12: =IF(H12="","",H12*10) | K12: Núm.elementos evaluados | L12: =10-(COUNTIF(C3:C12,"NA")+COUNTBLANK(C3:C12)) | M12: (no contabiliza ni los vacíos ni los NA)
G13: =IF(SUM(G3:G12)=0,"",SUM(G3:G12))
A14: Instrucciones | C14: Leyenda Valor
A15: 1. Evalue cada criterio y rellene la columna "Valor" según la leyenda | C15: 0 | D15: No se cumple en absoluto | F15: NEP | G15: No se cumple en los enlaces principales
A16: 2. Añada sus comentarios o la referencia a los mismos en otro documento anexo en la columna "Comentarios" | C16: 10 | D16: Se cumple totalmente | F16: NPP | G16: No se cumple en la página principal
C17: NA | D17: Criterio no aplicable en el sitio | F17: NPI | G17: No se cumple en alguna página interior
C18: NTS | D18: No se cumple en todo el sitio | F18: S | G18: Se cumple el criterio

Sheet 6, Entendibilidad y Facilidad
A1: CRITERIOS DEL "ENTENDIBILIDAD Y FACILIDAD EN LA INTERACCIÓN": Elementos relacionados con la adecuación y calidad de los contenidos textuales, iconos y controles de la interfaz.
A2: Código | B2: Criterio | C2: Valor | D2: Relevancia | E2: Comentarios | F2: Valor interno(vc) | G2: Valor interno de relevancia (rc) | H2: Factor de corrección (fc) | I2: Valor parcial | J2: Valor parcial 2
A3: EF.1 | B3: Se emplea un lenguaje claro y conciso | C3: 10 | D3: =IF(OR(TipoDeSitio="",C3="NA"),"",VLOOKUP(CONCATENATE(A3,": ",B3),Tabla626,MATCH(TipoDeSitio,Tipos,0)+1,0)) | E3: Párrafos cortos; etiquetas de campo directas: "Lugar de Origen", "Fecha del Traslado". | F3: =IF(C3="","",VLOOKUP(C3,ValoresVC,2,0)) | G3: =IF(D3="","",VLOOKUP($D3,ValoresRC,2,0)) | H3: =IF(OR(G3="",G3=0,'Cálculo de % usabilidad'!$F$5=0),"",G3/'Cálculo de % usabilidad'!$F$5) | I3: =IF(OR(H3="",F3=""),"",H3*F3) | J3: =IF(H3="","",H3*10)
A4: EF.2 | B4: Lenguaje amigable, familiar y cercano | C4: 10 | D4: =IF(OR(TipoDeSitio="",C4="NA"),"",VLOOKUP(CONCATENATE(A4,": ",B4),Tabla626,MATCH(TipoDeSitio,Tipos,0)+1,0)) | E4: Tono informativo y amable sin tecnicismos. | F4: =IF(C4="","",VLOOKUP(C4,ValoresVC,2,0)) | G4: =IF(D4="","",VLOOKUP($D4,ValoresRC,2,0)) | H4: =IF(OR(G4="",G4=0,'Cálculo de % usabilidad'!$F$5=0),"",G4/'Cálculo de % usabilidad'!$F$5) | I4: =IF(OR(H4="",F4=""),"",H4*F4) | J4: =IF(H4="","",H4*10)
A5: EF.3 | B5: Cada párrafo expresa una idea | C5: 10 | D5: =IF(OR(TipoDeSitio="",C5="NA"),"",VLOOKUP(CONCATENATE(A5,": ",B5),Tabla626,MATCH(TipoDeSitio,Tipos,0)+1,0)) | E5: Cada bloque de texto tiene un único propósito semántico. | F5: =IF(C5="","",VLOOKUP(C5,ValoresVC,2,0)) | G5: =IF(D5="","",VLOOKUP($D5,ValoresRC,2,0)) | H5: =IF(OR(G5="",G5=0,'Cálculo de % usabilidad'!$F$5=0),"",G5/'Cálculo de % usabilidad'!$F$5) | I5: =IF(OR(H5="",F5=""),"",H5*F5) | J5: =IF(H5="","",H5*10)
A6: EF.4 | B6: Uso consistente de los controles de la interfaz | C6: 10 | D6: =IF(OR(TipoDeSitio="",C6="NA"),"",VLOOKUP(CONCATENATE(A6,": ",B6),Tabla626,MATCH(TipoDeSitio,Tipos,0)+1,0)) | E6: Botones, selects e inputs siguen el patrón Bootstrap en todas las páginas. | F6: =IF(C6="","",VLOOKUP(C6,ValoresVC,2,0)) | G6: =IF(D6="","",VLOOKUP($D6,ValoresRC,2,0)) | H6: =IF(OR(G6="",G6=0,'Cálculo de % usabilidad'!$F$5=0),"",G6/'Cálculo de % usabilidad'!$F$5) | I6: =IF(OR(H6="",F6=""),"",H6*F6) | J6: =IF(H6="","",H6*10)
A7: EF.5 | B7: Metáforas visuales reconocibles y comprensibles por cualquier usuario (ej.: iconos) | C7: 10 | D7: =IF(OR(TipoDeSitio="",C7="NA"),"",VLOOKUP(CONCATENATE(A7,": ",B7),Tabla626,MATCH(TipoDeSitio,Tipos,0)+1,0)) | E7: Iconos de emoji (📍📞✉️) en la página de contacto; iconos de tema/idioma en la nav. | F7: =IF(C7="","",VLOOKUP(C7,ValoresVC,2,0)) | G7: =IF(D7="","",VLOOKUP($D7,ValoresRC,2,0)) | H7: =IF(OR(G7="",G7=0,'Cálculo de % usabilidad'!$F$5=0),"",G7/'Cálculo de % usabilidad'!$F$5) | I7: =IF(OR(H7="",F7=""),"",H7*F7) | J7: =IF(H7="","",H7*10)
A8: EF.6 | B8: Si se usan menús desplegables, orden coherente o alfabético | C8: 10 | D8: =IF(OR(TipoDeSitio="",C8="NA"),"",VLOOKUP(CONCATENATE(A8,": ",B8),Tabla626,MATCH(TipoDeSitio,Tipos,0)+1,0)) | E8: Lista de destinos en orden geográfico lógico; extras en orden lógico. | F8: =IF(C8="","",VLOOKUP(C8,ValoresVC,2,0)) | G8: =IF(D8="","",VLOOKUP($D8,ValoresRC,2,0)) | H8: =IF(OR(G8="",G8=0,'Cálculo de % usabilidad'!$F$5=0),"",G8/'Cálculo de % usabilidad'!$F$5) | I8: =IF(OR(H8="",F8=""),"",H8*F8) | J8: =IF(H8="","",H8*10)
A9: EF.7 | B9: Si el usuario tiene que rellenar un campo, las opciones disponibles se pueden seleccionar en vez de tener que escribirlas | C9: 10 | D9: =IF(OR(TipoDeSitio="",C9="NA"),"",VLOOKUP(CONCATENATE(A9,": ",B9),Tabla626,MATCH(TipoDeSitio,Tipos,0)+1,0)) | E9: Origen, destino, extras y número de pasajeros usan <select> e <input> estándar. | F9: =IF(C9="","",VLOOKUP(C9,ValoresVC,2,0)) | G9: =IF(D9="","",VLOOKUP($D9,ValoresRC,2,0)) | H9: =IF(OR(G9="",G9=0,'Cálculo de % usabilidad'!$F$5=0),"",G9/'Cálculo de % usabilidad'!$F$5) | I9: =IF(OR(H9="",F9=""),"",H9*F9) | J9: =IF(H9="","",H9*10) | K9: Núm.elementos evaluados | L9: =7-(COUNTIF(C3:C9,"NA")+COUNTBLANK(C3:C9)) | M9: (no contabiliza ni los vacíos ni los NA)
G10: =IF(SUM(G3:G9)=0,"",SUM(G3:G9))
A11: Instrucciones | C11: Leyenda Valor
A12: 1. Evalue cada criterio y rellene la columna "Valor" según la leyenda | C12: 0 | D12: No se cumple en absoluto | F12: NEP | G12: No se cumple en los enlaces principales
A13: 2. Añada sus comentarios o la referencia a los mismos en otro documento anexo en la columna "Comentarios" | C13: 10 | D13: Se cumple totalmente | F13: NPP | G13: No se cumple en la página principal
C14: NA | D14: Criterio no aplicable en el sitio | F14: NPI | G14: No se cumple en alguna página interior
C15: NTS | D15: No se cumple en todo el sitio | F15: S | G15: Se cumple el criterio

Sheet 7, Control y Retoalimentación
A1: CRITERIOS DEL "CONTROL Y RETORALIMENTACIÓN": Elementos relacionados con libertad del usuario en la navegación y la información proporcionada al mismo en el proceso de interacción con el sitio.
A2: Código | B2: Criterio | C2: Valor | D2: Relevancia | E2: Comentarios | F2: Valor interno(vc) | G2: Valor interno de relevancia (rc) | H2: Factor de corrección (fc) | I2: Valor parcial | J2: Valor parcial 2
A3: CR.1 | B3: El usuario tiene todo el control sobre la interfaz | C3: 10 | D3: =IF(OR(TipoDeSitio="",C3="NA"),"",VLOOKUP(CONCATENATE(A3,": ",B3),Tabla627,MATCH(TipoDeSitio,Tipos,0)+1,0)) | E3: El usuario puede navegar libremente, cancelar modales y modificar datos. | F3: =IF(C3="","",VLOOKUP(C3,ValoresVC,2,0)) | G3: =IF(D3="","",VLOOKUP($D3,ValoresRC,2,0)) | H3: =IF(OR(G3="",G3=0,'Cálculo de % usabilidad'!$F$5=0),"",G3/'Cálculo de % usabilidad'!$F$5) | I3: =IF(OR(H3="",F3=""),"",H3*F3) | J3: =IF(H3="","",H3*10)
A4: CR.2 | B4: Se informa al usuario acerca de lo que está pasando | C4: 10 | D4: =IF(OR(TipoDeSitio="",C4="NA"),"",VLOOKUP(CONCATENATE(A4,": ",B4),Tabla627,MATCH(TipoDeSitio,Tipos,0)+1,0)) | E4: Modal de confirmación muestra resumen antes de pagar; precio se actualiza en tiempo real. | F4: =IF(C4="","",VLOOKUP(C4,ValoresVC,2,0)) | G4: =IF(D4="","",VLOOKUP($D4,ValoresRC,2,0)) | H4: =IF(OR(G4="",G4=0,'Cálculo de % usabilidad'!$F$5=0),"",G4/'Cálculo de % usabilidad'!$F$5) | I4: =IF(OR(H4="",F4=""),"",H4*F4) | J4: =IF(H4="","",H4*10)
A5: CR.3 | B5: Se informa al usuario de lo que ha pasado | C5: 10 | D5: =IF(OR(TipoDeSitio="",C5="NA"),"",VLOOKUP(CONCATENATE(A5,": ",B5),Tabla627,MATCH(TipoDeSitio,Tipos,0)+1,0)) | E5: Código de reserva TX-12345 generado y mostrado al finalizar el pago. | F5: =IF(C5="","",VLOOKUP(C5,ValoresVC,2,0)) | G5: =IF(D5="","",VLOOKUP($D5,ValoresRC,2,0)) | H5: =IF(OR(G5="",G5=0,'Cálculo de % usabilidad'!$F$5=0),"",G5/'Cálculo de % usabilidad'!$F$5) | I5: =IF(OR(H5="",F5=""),"",H5*F5) | J5: =IF(H5="","",H5*10)
A6: CR.4 | B6: Existen sistemas de validación antes de que el usuario envíe información para tratar de evitar errores | C6: 10 | D6: =IF(OR(TipoDeSitio="",C6="NA"),"",VLOOKUP(CONCATENATE(A6,": ",B6),Tabla627,MATCH(TipoDeSitio,Tipos,0)+1,0)) | E6: bookingValidation.js valida todos los campos antes de mostrar el modal de confirmación. | F6: =IF(C6="","",VLOOKUP(C6,ValoresVC,2,0)) | G6: =IF(D6="","",VLOOKUP($D6,ValoresRC,2,0)) | H6: =IF(OR(G6="",G6=0,'Cálculo de % usabilidad'!$F$5=0),"",G6/'Cálculo de % usabilidad'!$F$5) | I6: =IF(OR(H6="",F6=""),"",H6*F6) | J6: =IF(H6="","",H6*10)
A7: CR.5 | B7: Cuando se produce un error, se informa de forma clara y no alarmista al usuario de lo ocurrido y de cómo solucionar el problema | C7: 10 | D7: =IF(OR(TipoDeSitio="",C7="NA"),"",VLOOKUP(CONCATENATE(A7,": ",B7),Tabla627,MATCH(TipoDeSitio,Tipos,0)+1,0)) | E7: Mensajes de error inline junto a cada campo inválido. | F7: =IF(C7="","",VLOOKUP(C7,ValoresVC,2,0)) | G7: =IF(D7="","",VLOOKUP($D7,ValoresRC,2,0)) | H7: =IF(OR(G7="",G7=0,'Cálculo de % usabilidad'!$F$5=0),"",G7/'Cálculo de % usabilidad'!$F$5) | I7: =IF(OR(H7="",F7=""),"",H7*F7) | J7: =IF(H7="","",H7*10)
A8: CR.6 | B8: Se ha controlado el tiempo de respuesta | C8: 10 | D8: =IF(OR(TipoDeSitio="",C8="NA"),"",VLOOKUP(CONCATENATE(A8,": ",B8),Tabla627,MATCH(TipoDeSitio,Tipos,0)+1,0)) | E8: Todo el procesamiento es en cliente; sin latencia de red. | F8: =IF(C8="","",VLOOKUP(C8,ValoresVC,2,0)) | G8: =IF(D8="","",VLOOKUP($D8,ValoresRC,2,0)) | H8: =IF(OR(G8="",G8=0,'Cálculo de % usabilidad'!$F$5=0),"",G8/'Cálculo de % usabilidad'!$F$5) | I8: =IF(OR(H8="",F8=""),"",H8*F8) | J8: =IF(H8="","",H8*10)
A9: CR.7 | B9: Se ha evitado que las ventanas del sitio anulen o se superpongan a la del navegador | C9: 10 | D9: =IF(OR(TipoDeSitio="",C9="NA"),"",VLOOKUP(CONCATENATE(A9,": ",B9),Tabla627,MATCH(TipoDeSitio,Tipos,0)+1,0)) | E9: Los modales Bootstrap no abren ventanas nuevas; se superponen en la misma pestaña. | F9: =IF(C9="","",VLOOKUP(C9,ValoresVC,2,0)) | G9: =IF(D9="","",VLOOKUP($D9,ValoresRC,2,0)) | H9: =IF(OR(G9="",G9=0,'Cálculo de % usabilidad'!$F$5=0),"",G9/'Cálculo de % usabilidad'!$F$5) | I9: =IF(OR(H9="",F9=""),"",H9*F9) | J9: =IF(H9="","",H9*10)
A10: CR.8 | B10: Se ha evitado la proliferación de ventanas en la pantalla del usuario | C10: 10 | D10: =IF(OR(TipoDeSitio="",C10="NA"),"",VLOOKUP(CONCATENATE(A10,": ",B10),Tabla627,MATCH(TipoDeSitio,Tipos,0)+1,0)) | E10: Máximo un modal visible a la vez (confirmación o pago). | F10: =IF(C10="","",VLOOKUP(C10,ValoresVC,2,0)) | G10: =IF(D10="","",VLOOKUP($D10,ValoresRC,2,0)) | H10: =IF(OR(G10="",G10=0,'Cálculo de % usabilidad'!$F$5=0),"",G10/'Cálculo de % usabilidad'!$F$5) | I10: =IF(OR(H10="",F10=""),"",H10*F10) | J10: =IF(H10="","",H10*10)
A11: CR.9 | B11: Se ha evitado la descarga por parte del usuario de plugins adicionales | C11: 10 | D11: =IF(OR(TipoDeSitio="",C11="NA"),"",VLOOKUP(CONCATENATE(A11,": ",B11),Tabla627,MATCH(TipoDeSitio,Tipos,0)+1,0)) | E11: Solo se requiere Bootstrap CDN; no hay plugins propietarios. | F11: =IF(C11="","",VLOOKUP(C11,ValoresVC,2,0)) | G11: =IF(D11="","",VLOOKUP($D11,ValoresRC,2,0)) | H11: =IF(OR(G11="",G11=0,'Cálculo de % usabilidad'!$F$5=0),"",G11/'Cálculo de % usabilidad'!$F$5) | I11: =IF(OR(H11="",F11=""),"",H11*F11) | J11: =IF(H11="","",H11*10)
A12: CR.10 | B12: Si existen tareas de varios pasos, se indica al usuario en cual está y cuantos faltan para completar la tarea | C12: 7 | D12: =IF(OR(TipoDeSitio="",C12="NA"),"",VLOOKUP(CONCATENATE(A12,": ",B12),Tabla627,MATCH(TipoDeSitio,Tipos,0)+1,0)) | E12: Los modales indican la fase (Confirmar / Pagar) pero no muestran "Paso X de Y". | F12: =IF(C12="","",VLOOKUP(C12,ValoresVC,2,0)) | G12: =IF(D12="","",VLOOKUP($D12,ValoresRC,2,0)) | H12: =IF(OR(G12="",G12=0,'Cálculo de % usabilidad'!$F$5=0),"",G12/'Cálculo de % usabilidad'!$F$5) | I12: =IF(OR(H12="",F12=""),"",H12*F12) | J12: =IF(H12="","",H12*10) | K12: Núm.elementos evaluados | L12: =10-(COUNTIF(C3:C12,"NA")+COUNTBLANK(C3:C12)) | M12: (no contabiliza ni los vacíos ni los NA)
G13: =IF(SUM(G3:G12)=0,"",SUM(G3:G12))
A14: Instrucciones | C14: Leyenda Valor
A15: 1. Evalue cada criterio y rellene la columna "Valor" según la leyenda | C15: 0 | D15: No se cumple en absoluto | F15: NEP | G15: No se cumple en los enlaces principales
A16: 2. Añada sus comentarios o la referencia a los mismos en otro documento anexo en la columna "Comentarios" | C16: 10 | D16: Se cumple totalmente | F16: NPP | G16: No se cumple en la página principal
C17: NA | D17: Criterio no aplicable en el sitio | F17: NPI | G17: No se cumple en alguna página interior
C18: NTS | D18: No se cumple en todo el sitio | F18: S | G18: Se cumple el criterio

Sheet 8, Elementos multimedia
A1: CRITERIOS DEL "ELEMENTOS MULTIMEDIA": Elementos relacionados con el grado de adecuación de los contenidos multimedia al sitio web.
A2: Código | B2: Criterio | C2: Valor | D2: Relevancia | E2: Comentarios | F2: Valor interno(vc) | G2: Valor interno de relevancia (rc) | H2: Factor de corrección (fc) | I2: Valor parcial | J2: Valor parcial 2
A3: EM.1 | B3: Fotografías bien recortadas | C3: NA | D3: =IF(OR(TipoDeSitio="",C3="NA"),"",VLOOKUP(CONCATENATE(A3,": ",B3),Tabla628,MATCH(TipoDeSitio,Tipos,0)+1,0)) | E3: El prototipo no incluye fotografías. | F3: =IF(C3="","",VLOOKUP(C3,ValoresVC,2,0)) | G3: =IF(D3="","",VLOOKUP($D3,ValoresRC,2,0)) | H3: =IF(OR(G3="",G3=0,'Cálculo de % usabilidad'!$F$5=0),"",G3/'Cálculo de % usabilidad'!$F$5) | I3: =IF(OR(H3="",F3=""),"",H3*F3) | J3: =IF(H3="","",H3*10)
A4: EM.2 | B4: Fotografías comprensibles | C4: NA | D4: =IF(OR(TipoDeSitio="",C4="NA"),"",VLOOKUP(CONCATENATE(A4,": ",B4),Tabla628,MATCH(TipoDeSitio,Tipos,0)+1,0)) | E4: El prototipo no incluye fotografías. | F4: =IF(C4="","",VLOOKUP(C4,ValoresVC,2,0)) | G4: =IF(D4="","",VLOOKUP($D4,ValoresRC,2,0)) | H4: =IF(OR(G4="",G4=0,'Cálculo de % usabilidad'!$F$5=0),"",G4/'Cálculo de % usabilidad'!$F$5) | I4: =IF(OR(H4="",F4=""),"",H4*F4) | J4: =IF(H4="","",H4*10)
A5: EM.3 | B5: Fotografías con correcta resolución | C5: NA | D5: =IF(OR(TipoDeSitio="",C5="NA"),"",VLOOKUP(CONCATENATE(A5,": ",B5),Tabla628,MATCH(TipoDeSitio,Tipos,0)+1,0)) | E5: El prototipo no incluye fotografías. | F5: =IF(C5="","",VLOOKUP(C5,ValoresVC,2,0)) | G5: =IF(D5="","",VLOOKUP($D5,ValoresRC,2,0)) | H5: =IF(OR(G5="",G5=0,'Cálculo de % usabilidad'!$F$5=0),"",G5/'Cálculo de % usabilidad'!$F$5) | I5: =IF(OR(H5="",F5=""),"",H5*F5) | J5: =IF(H5="","",H5*10)
A6: EM.4 | B6: El uso de imágenes o animaciones proporciona algún tipo de valor añadido | C6: 8 | D6: =IF(OR(TipoDeSitio="",C6="NA"),"",VLOOKUP(CONCATENATE(A6,": ",B6),Tabla628,MATCH(TipoDeSitio,Tipos,0)+1,0)) | E6: El logo SVG de taxi refuerza la identidad visual del servicio. | F6: =IF(C6="","",VLOOKUP(C6,ValoresVC,2,0)) | G6: =IF(D6="","",VLOOKUP($D6,ValoresRC,2,0)) | H6: =IF(OR(G6="",G6=0,'Cálculo de % usabilidad'!$F$5=0),"",G6/'Cálculo de % usabilidad'!$F$5) | I6: =IF(OR(H6="",F6=""),"",H6*F6) | J6: =IF(H6="","",H6*10)
A7: EM.5 | B7: Se ha evitado el uso de animaciones cíclicas | C7: 10 | D7: =IF(OR(TipoDeSitio="",C7="NA"),"",VLOOKUP(CONCATENATE(A7,": ",B7),Tabla628,MATCH(TipoDeSitio,Tipos,0)+1,0)) | E7: No se usan animaciones GIF ni CSS en bucle. | F7: =IF(C7="","",VLOOKUP(C7,ValoresVC,2,0)) | G7: =IF(D7="","",VLOOKUP($D7,ValoresRC,2,0)) | H7: =IF(OR(G7="",G7=0,'Cálculo de % usabilidad'!$F$5=0),"",G7/'Cálculo de % usabilidad'!$F$5) | I7: =IF(OR(H7="",F7=""),"",H7*F7) | J7: =IF(H7="","",H7*10)
A8: EM.6 | B8: El uso de sonido proporciona algún tipo de valor añadido | C8: NA | D8: =IF(OR(TipoDeSitio="",C8="NA"),"",VLOOKUP(CONCATENATE(A8,": ",B8),Tabla628,MATCH(TipoDeSitio,Tipos,0)+1,0)) | E8: El prototipo no incluye audio. | F8: =IF(C8="","",VLOOKUP(C8,ValoresVC,2,0)) | G8: =IF(D8="","",VLOOKUP($D8,ValoresRC,2,0)) | H8: =IF(OR(G8="",G8=0,'Cálculo de % usabilidad'!$F$5=0),"",G8/'Cálculo de % usabilidad'!$F$5) | I8: =IF(OR(H8="",F8=""),"",H8*F8) | J8: =IF(H8="","",H8*10) | K8: Núm.elementos evaluados | L8: =6-(COUNTIF(C3:C8,"NA")+COUNTBLANK(C3:C8)) | M8: (no contabiliza ni los vacíos ni los NA)
G9: =IF(SUM(G3:G8)=0,"",SUM(G3:G8))
A10: Instrucciones | C10: Leyenda Valor
A11: 1. Evalue cada criterio y rellene la columna "Valor" según la leyenda | C11: 0 | D11: No se cumple en absoluto | F11: NEP | G11: No se cumple en los enlaces principales
A12: 2. Añada sus comentarios o la referencia a los mismos en otro documento anexo en la columna "Comentarios" | C12: 10 | D12: Se cumple totalmente | F12: NPP | G12: No se cumple en la página principal
C13: NA | D13: Criterio no aplicable en el sitio | F13: NPI | G13: No se cumple en alguna página interior
C14: NTS | D14: No se cumple en todo el sitio | F14: S | G14: Se cumple el criterio

Sheet 9, Búsqueda
A1: CRITERIOS DEL "BÚSQUEDA": Elementos relacionados con el buscador implementado en el sitio web.
A2: Código | B2: Criterio | C2: Valor | D2: Relevancia | E2: Comentarios | F2: Valor interno(vc) | G2: Valor interno de relevancia (rc) | H2: Factor de corrección (fc) | I2: Valor parcial | J2: Valor parcial 2
A3: BU.1 | B3: La búsqueda, si es necesaria, se encuentra accesible desde todas las páginas del sitio | C3: NA | D3: =IF(OR(TipoDeSitio="",C3="NA"),"",VLOOKUP(CONCATENATE(A3,": ",B3),Tabla629,MATCH(TipoDeSitio,Tipos,0)+1,0)) | E3: No se implementa buscador global; la localización de reservas es un flujo específico. | F3: =IF(C3="","",VLOOKUP(C3,ValoresVC,2,0)) | G3: =IF(D3="","",VLOOKUP($D3,ValoresRC,2,0)) | H3: =IF(OR(G3="",G3=0,'Cálculo de % usabilidad'!$F$5=0),"",G3/'Cálculo de % usabilidad'!$F$5) | I3: =IF(OR(H3="",F3=""),"",H3*F3) | J3: =IF(H3="","",H3*10)
A4: BU.2 | B4: Es fácilmente reconocible como tal | C4: NA | D4: =IF(OR(TipoDeSitio="",C4="NA"),"",VLOOKUP(CONCATENATE(A4,": ",B4),Tabla629,MATCH(TipoDeSitio,Tipos,0)+1,0)) | E4: No aplica. | F4: =IF(C4="","",VLOOKUP(C4,ValoresVC,2,0)) | G4: =IF(D4="","",VLOOKUP($D4,ValoresRC,2,0)) | H4: =IF(OR(G4="",G4=0,'Cálculo de % usabilidad'!$F$5=0),"",G4/'Cálculo de % usabilidad'!$F$5) | I4: =IF(OR(H4="",F4=""),"",H4*F4) | J4: =IF(H4="","",H4*10)
A5: BU.3 | B5: Se encuentra fácilmente accesible | C5: NA | D5: =IF(OR(TipoDeSitio="",C5="NA"),"",VLOOKUP(CONCATENATE(A5,": ",B5),Tabla629,MATCH(TipoDeSitio,Tipos,0)+1,0)) | E5: No aplica. | F5: =IF(C5="","",VLOOKUP(C5,ValoresVC,2,0)) | G5: =IF(D5="","",VLOOKUP($D5,ValoresRC,2,0)) | H5: =IF(OR(G5="",G5=0,'Cálculo de % usabilidad'!$F$5=0),"",G5/'Cálculo de % usabilidad'!$F$5) | I5: =IF(OR(H5="",F5=""),"",H5*F5) | J5: =IF(H5="","",H5*10)
A6: BU.4 | B6: La caja de texto es lo suficientemente ancha | C6: NA | D6: =IF(OR(TipoDeSitio="",C6="NA"),"",VLOOKUP(CONCATENATE(A6,": ",B6),Tabla629,MATCH(TipoDeSitio,Tipos,0)+1,0)) | E6: No aplica. | F6: =IF(C6="","",VLOOKUP(C6,ValoresVC,2,0)) | G6: =IF(D6="","",VLOOKUP($D6,ValoresRC,2,0)) | H6: =IF(OR(G6="",G6=0,'Cálculo de % usabilidad'!$F$5=0),"",G6/'Cálculo de % usabilidad'!$F$5) | I6: =IF(OR(H6="",F6=""),"",H6*F6) | J6: =IF(H6="","",H6*10)
A7: BU.5 | B7: Sistema de búsqueda simple y claro | C7: NA | D7: =IF(OR(TipoDeSitio="",C7="NA"),"",VLOOKUP(CONCATENATE(A7,": ",B7),Tabla629,MATCH(TipoDeSitio,Tipos,0)+1,0)) | E7: No aplica. | F7: =IF(C7="","",VLOOKUP(C7,ValoresVC,2,0)) | G7: =IF(D7="","",VLOOKUP($D7,ValoresRC,2,0)) | H7: =IF(OR(G7="",G7=0,'Cálculo de % usabilidad'!$F$5=0),"",G7/'Cálculo de % usabilidad'!$F$5) | I7: =IF(OR(H7="",F7=""),"",H7*F7) | J7: =IF(H7="","",H7*10)
A8: BU.6 | B8: Permite la búsqueda avanzada | C8: NA | D8: =IF(OR(TipoDeSitio="",C8="NA"),"",VLOOKUP(CONCATENATE(A8,": ",B8),Tabla629,MATCH(TipoDeSitio,Tipos,0)+1,0)) | E8: No aplica. | F8: =IF(C8="","",VLOOKUP(C8,ValoresVC,2,0)) | G8: =IF(D8="","",VLOOKUP($D8,ValoresRC,2,0)) | H8: =IF(OR(G8="",G8=0,'Cálculo de % usabilidad'!$F$5=0),"",G8/'Cálculo de % usabilidad'!$F$5) | I8: =IF(OR(H8="",F8=""),"",H8*F8) | J8: =IF(H8="","",H8*10)
A9: BU.7 | B9: Muestra los resultados de la búsqueda de forma comprensible para el usuario | C9: NA | D9: =IF(OR(TipoDeSitio="",C9="NA"),"",VLOOKUP(CONCATENATE(A9,": ",B9),Tabla629,MATCH(TipoDeSitio,Tipos,0)+1,0)) | E9: No aplica. | F9: =IF(C9="","",VLOOKUP(C9,ValoresVC,2,0)) | G9: =IF(D9="","",VLOOKUP($D9,ValoresRC,2,0)) | H9: =IF(OR(G9="",G9=0,'Cálculo de % usabilidad'!$F$5=0),"",G9/'Cálculo de % usabilidad'!$F$5) | I9: =IF(OR(H9="",F9=""),"",H9*F9) | J9: =IF(H9="","",H9*10)
A10: BU.8 | B10: Asiste al usuario en caso de no poder ofrecer resultados para una consulta dada | C10: NA | D10: =IF(OR(TipoDeSitio="",C10="NA"),"",VLOOKUP(CONCATENATE(A10,": ",B10),Tabla629,MATCH(TipoDeSitio,Tipos,0)+1,0)) | E10: No aplica. | F10: =IF(C10="","",VLOOKUP(C10,ValoresVC,2,0)) | G10: =IF(D10="","",VLOOKUP($D10,ValoresRC,2,0)) | H10: =IF(OR(G10="",G10=0,'Cálculo de % usabilidad'!$F$5=0),"",G10/'Cálculo de % usabilidad'!$F$5) | I10: =IF(OR(H10="",F10=""),"",H10*F10) | J10: =IF(H10="","",H10*10) | K10: Núm.elementos evaluados | L10: =8-(COUNTIF(C3:C10,"NA")+COUNTBLANK(C3:C10)) | M10: (no contabiliza ni los vacíos ni los NA)
G11: =IF(SUM(G3:G10)=0,"",SUM(G3:G10))
A12: Instrucciones | C12: Leyenda Valor
A13: 1. Evalue cada criterio y rellene la columna "Valor" según la leyenda | C13: 0 | D13: No se cumple en absoluto | F13: NEP | G13: No se cumple en los enlaces principales
A14: 2. Añada sus comentarios o la referencia a los mismos en otro documento anexo en la columna "Comentarios" | C14: 10 | D14: Se cumple totalmente | F14: NPP | G14: No se cumple en la página principal
C15: NA | D15: Criterio no aplicable en el sitio | F15: NPI | G15: No se cumple en alguna página interior
C16: NTS | D16: No se cumple en todo el sitio | F16: S | G16: Se cumple el criterio

Sheet 10, Ayuda
A1: CRITERIOS DEL "AYUDA": Elementos relacionados con la ayuda ofrecida al usuario durante la navegación por el sitio.
A2: Código | B2: Criterio | C2: Valor | D2: Relevancia | E2: Comentarios | F2: Valor interno(vc) | G2: Valor interno de relevancia (rc) | H2: Factor de corrección (fc) | I2: Valor parcial | J2: Valor parcial 2
A3: AY.1 | B3: El enlace a la sección de Ayuda está colocado en una zona visible y estándar | C3: 0 | D3: =IF(OR(TipoDeSitio="",C3="NA"),"",VLOOKUP(CONCATENATE(A3,": ",B3),Tabla630,MATCH(TipoDeSitio,Tipos,0)+1,0)) | E3: No existe página ni enlace de Ayuda en el sitio. | F3: =IF(C3="","",VLOOKUP(C3,ValoresVC,2,0)) | G3: =IF(D3="","",VLOOKUP($D3,ValoresRC,2,0)) | H3: =IF(OR(G3="",G3=0,'Cálculo de % usabilidad'!$F$5=0),"",G3/'Cálculo de % usabilidad'!$F$5) | I3: =IF(OR(H3="",F3=""),"",H3*F3) | J3: =IF(H3="","",H3*10)
A4: AY.2 | B4: Fácil acceso y retorno al/del sistema de ayuda | C4: 0 | D4: =IF(OR(TipoDeSitio="",C4="NA"),"",VLOOKUP(CONCATENATE(A4,": ",B4),Tabla630,MATCH(TipoDeSitio,Tipos,0)+1,0)) | E4: No existe sistema de ayuda al que acceder o del que volver. | F4: =IF(C4="","",VLOOKUP(C4,ValoresVC,2,0)) | G4: =IF(D4="","",VLOOKUP($D4,ValoresRC,2,0)) | H4: =IF(OR(G4="",G4=0,'Cálculo de % usabilidad'!$F$5=0),"",G4/'Cálculo de % usabilidad'!$F$5) | I4: =IF(OR(H4="",F4=""),"",H4*F4) | J4: =IF(H4="","",H4*10)
A5: AY.3 | B5: Se ofrece ayuda contextual en tareas complejas | C5: 7 | D5: =IF(OR(TipoDeSitio="",C5="NA"),"",VLOOKUP(CONCATENATE(A5,": ",B5),Tabla630,MATCH(TipoDeSitio,Tipos,0)+1,0)) | E5: Los campos del formulario incluyen textos de ayuda (form-text Bootstrap) como "Selecciona un destino disponible de Tenerife" e indicaciones de hora y fecha. | F5: =IF(C5="","",VLOOKUP(C5,ValoresVC,2,0)) | G5: =IF(D5="","",VLOOKUP($D5,ValoresRC,2,0)) | H5: =IF(OR(G5="",G5=0,'Cálculo de % usabilidad'!$F$5=0),"",G5/'Cálculo de % usabilidad'!$F$5) | I5: =IF(OR(H5="",F5=""),"",H5*F5) | J5: =IF(H5="","",H5*10)
A6: AY.4 | B6: FAQs (si las hay) correcta la elección como la redacción de las preguntas | C6: NA | D6: =IF(OR(TipoDeSitio="",C6="NA"),"",VLOOKUP(CONCATENATE(A6,": ",B6),Tabla630,MATCH(TipoDeSitio,Tipos,0)+1,0)) | E6: No hay sección de preguntas frecuentes. | F6: =IF(C6="","",VLOOKUP(C6,ValoresVC,2,0)) | G6: =IF(D6="","",VLOOKUP($D6,ValoresRC,2,0)) | H6: =IF(OR(G6="",G6=0,'Cálculo de % usabilidad'!$F$5=0),"",G6/'Cálculo de % usabilidad'!$F$5) | I6: =IF(OR(H6="",F6=""),"",H6*F6) | J6: =IF(H6="","",H6*10)
A7: AY.5 | B7: FAQs (si las hay) correcta la redacción de las respuestas | C7: NA | D7: =IF(OR(TipoDeSitio="",C7="NA"),"",VLOOKUP(CONCATENATE(A7,": ",B7),Tabla630,MATCH(TipoDeSitio,Tipos,0)+1,0)) | E7: No hay sección de preguntas frecuentes. | F7: =IF(C7="","",VLOOKUP(C7,ValoresVC,2,0)) | G7: =IF(D7="","",VLOOKUP($D7,ValoresRC,2,0)) | H7: =IF(OR(G7="",G7=0,'Cálculo de % usabilidad'!$F$5=0),"",G7/'Cálculo de % usabilidad'!$F$5) | I7: =IF(OR(H7="",F7=""),"",H7*F7) | J7: =IF(H7="","",H7*10) | K7: Núm.elementos evaluados | L7: =5-(COUNTIF(C3:C7,"NA")+COUNTBLANK(C3:C7)) | M7: (no contabiliza ni los vacíos ni los NA)
G8: =IF(SUM(G3:G7)=0,"",SUM(G3:G7))
A9: Instrucciones | C9: Leyenda Valor
A10: 1. Evalue cada criterio y rellene la columna "Valor" según la leyenda | C10: 0 | D10: No se cumple en absoluto | F10: NEP | G10: No se cumple en los enlaces principales
A11: 2. Añada sus comentarios o la referencia a los mismos en otro documento anexo en la columna "Comentarios" | C11: 10 | D11: Se cumple totalmente | F11: NPP | G11: No se cumple en la página principal
C12: NA | D12: Criterio no aplicable en el sitio | F12: NPI | G12: No se cumple en alguna página interior
C13: NTS | D13: No se cumple en todo el sitio | F13: S | G13: Se cumple el criterio

Sheet Cálculo de % usabilidad
A2: CÁLCULO DEL PORCENTAJE DE USABILIDAD
D3: Datos para el cálculo:
A4: Porcentaje de usabilidad* | B4: =IF(OR(ISERROR(F6),ISERROR(F7),F6="",F7="",F6=0,F7=0),"",(F6/F7)*100) | D4: Nº de criterios evaluados | F4: =SUM('1, Aspectos generales'!L12,'2, Identidad e Información'!L9,'3, Estructura y navegación'!L16,'4, Rotulado'!L8,'5, Layout de la página'!L12,'6, Entendibilidad y Facilidad'!L9,'7, Control y Retoalimentación'!L12,'8, Elementos multimedia'!L8,'9, Búsqueda'!L10,'10, Ayuda'!L7)
D5: El sumatorio de los valores de relevancia de los criterios evaluados es: | F5: =SUM('1, Aspectos generales'!G13,'2, Identidad e Información'!G10,'3, Estructura y navegación'!G17,'4, Rotulado'!G9,'5, Layout de la página'!G13,'6, Entendibilidad y Facilidad'!G10,'7, Control y Retoalimentación'!G13,'8, Elementos multimedia'!G9,'9, Búsqueda'!G11,'10, Ayuda'!G8) | G5: *A los NA no se les aplica relevancia
D6: Sumatorio de la columna i de cada criterio | F6: =SUM('1, Aspectos generales'!I3:I12,'2, Identidad e Información'!I3:I9,'3, Estructura y navegación'!I3:I16,'4, Rotulado'!I3:I8,'5, Layout de la página'!I3:I12,'6, Entendibilidad y Facilidad'!I3:I9,'7, Control y Retoalimentación'!I3:I12,'8, Elementos multimedia'!I3:I8,'9, Búsqueda'!I3:I10,'10, Ayuda'!I3:I7) | G6: *Los NA no se tienen en cuenta
D7: Sumatorio de la columna h *10 de cada criterio | F7: =SUM('1, Aspectos generales'!J3:J12,'2, Identidad e Información'!J3:J9,'3, Estructura y navegación'!J3:J16,'4, Rotulado'!J3:J8,'5, Layout de la página'!J3:J12,'7, Control y Retoalimentación'!J3:J12,'8, Elementos multimedia'!J3:J8,'6, Entendibilidad y Facilidad'!J3:J9,'9, Búsqueda'!J3:J10,'10, Ayuda'!J3:J7) | G7: *Los NA no se tienen en cuenta
A8: Se obtiene de aplicar la siguiente fórmula:
B11: nce: número de criterios evaluados. Será como máximo los 83. Los NA no contabilizan. Se toma de la celda E14 de esta hoja (NumEval)
B12: vc: valor de evaluación de un criterio (campo de la columna f "Valor interno" de cada criterio en cada hoja)
B13: fc: Factor de corrección aplicado al criterio evaluado.
B14: El valor del factor de corrección de cada uno de los criterios evaluados se obtiene de la siguiente manera:
D17: rc : Valor de relevancia que corresponde a un criterio (campo de la columna g "Valor interno de Relevancia")

Sheet Tablas de relevancia
A1: TABLA 6.21. RELEVANCIA DEL INCUMPLIMIENTO DE LOS CRITERIOS DE "ASPECTOS GENERALES"
B2: Tipo de Sitio
